<!-- 
unit : 
    - distance : m
    - mass : kg
    - time : s
 -->

<robot xmlns:xacro="http://www.ros.org/wiki/xacro" name="Eden">

  <xacro:include filename="$(find arm)/src/urdf/materials.xacro" />


    <link name="origin">
        <origin xyz="0 0 0" rpy="0 0 0" />
    </link>

    <link name="base">
        <visual>
            <origin xyz="-0.06 4.48374e-18 0.06" rpy="-3.14159 1.5708 0" />
            <geometry>
                <mesh filename="package://arm/src/meshes/skf_7208.stl"/>
            </geometry>
            <material name="bearing_material"/>
        </visual>
        <collision>
            <origin xyz="-0.06 4.48374e-18 0.06" rpy="-3.14159 1.5708 0" />
            <geometry>
                <mesh filename="package://arm/src/meshes/skf_7208.stl"/>
            </geometry>
            <material name="bearing_material"/>
        </collision>
        <visual>
            <origin xyz="0.0025 1.00198e-14 0.052" rpy="-1.5708 -0 1.5708" />
            <geometry>
                <mesh filename="package://arm/src/meshes/xl430.stl"/>
            </geometry>
            <material name="xl430_material"/>
        </visual>
        <collision>
            <origin xyz="0.0025 1.00198e-14 0.052" rpy="-1.5708 -0 1.5708" />
            <geometry>
                <mesh filename="package://arm/src/meshes/xl430.stl"/>
            </geometry>
            <material name="xl430_material"/>
        </collision>
        <visual>
            <origin xyz="0.00249985 1.45751e-07 0.088" rpy="3.14159 -0 -1.5708" />
            <geometry>
                <mesh filename="package://arm/src/meshes/small_gear_pelvis.stl"/>
            </geometry>
            <material name="pvc"/>
        </visual>
        <collision>
            <origin xyz="0.00249985 1.45751e-07 0.088" rpy="3.14159 -0 -1.5708" />
            <geometry>
                <mesh filename="package://arm/src/meshes/small_gear_pelvis.stl"/>
            </geometry>
            <material name="pvc"/>
        </collision>
        <visual>
            <origin xyz="-0.06 4.48374e-18 0.026" rpy="-0 1.5708 0" />
            <geometry>
                <mesh filename="package://arm/src/meshes/skf_7208.stl"/>
            </geometry>
            <material name="bearing_material"/>
        </visual>
        <collision>
            <origin xyz="-0.06 4.48374e-18 0.026" rpy="-0 1.5708 0" />
            <geometry>
                <mesh filename="package://arm/src/meshes/skf_7208.stl"/>
            </geometry>
            <material name="bearing_material"/>
        </collision>
        <visual>
            <origin xyz="0.00249985 1.45751e-07 0.082" rpy="0 -0 -1.5708" />
            <geometry>
                <mesh filename="package://arm/src/meshes/motor_link_xl.stl"/>
            </geometry>
            <material name="pla"/>
        </visual>
        <collision>
            <origin xyz="0.00249985 1.45751e-07 0.082" rpy="0 -0 -1.5708" />
            <geometry>
                <mesh filename="package://arm/src/meshes/motor_link_xl.stl"/>
            </geometry>
            <material name="pla"/>
        </collision>
        <visual>
            <origin xyz="0 0 0" rpy="0 -0 0" />
            <geometry>
                <mesh filename="package://arm/src/meshes/bottom.stl"/>
            </geometry>
            <material name="plywood"/>
        </visual>
        <collision>
            <origin xyz="0 0 0" rpy="0 -0 0" />
            <geometry>
                <mesh filename="package://arm/src/meshes/bottom.stl"/>
            </geometry>
            <material name="plywood"/>
        </collision>
        <visual>
            <origin xyz="-6.93889e-18 0.115 0" rpy="0 -0 1.48691e-16" />
            <geometry>
                <mesh filename="package://arm/src/meshes/wall_side.stl"/>
            </geometry>
            <material name="plywood"/>
        </visual>
        <collision>
            <origin xyz="-6.93889e-18 0.115 0" rpy="0 -0 1.48691e-16" />
            <geometry>
                <mesh filename="package://arm/src/meshes/wall_side.stl"/>
            </geometry>
            <material name="plywood"/>
        </collision>
        <visual>
            <origin xyz="0 0 0" rpy="0 -0 0" />
            <geometry>
                <mesh filename="package://arm/src/meshes/adapteur.stl"/>
            </geometry>
            <material name="pla"/>
        </visual>
        <collision>
            <origin xyz="0 0 0" rpy="0 -0 0" />
            <geometry>
                <mesh filename="package://arm/src/meshes/adapteur.stl"/>
            </geometry>
            <material name="pla"/>
        </collision>
        <visual>
            <origin xyz="-6.93889e-18 6.93889e-18 0" rpy="0 -0 1.48691e-16" />
            <geometry>
                <mesh filename="package://arm/src/meshes/wall_side.stl"/>
            </geometry>
            <material name="plywood"/>
        </visual>
        <collision>
            <origin xyz="-6.93889e-18 6.93889e-18 0" rpy="0 -0 1.48691e-16" />
            <geometry>
                <mesh filename="package://arm/src/meshes/wall_side.stl"/>
            </geometry>
            <material name="plywood"/>
        </collision>
        <visual>
            <origin xyz="-2.77556e-17 -6.93889e-18 -8.67362e-19" rpy="0 -0 0" />
            <geometry>
                <mesh filename="package://arm/src/meshes/wall_front.stl"/>
            </geometry>
            <material name="plywood"/>
        </visual>
        <collision>
            <origin xyz="-2.77556e-17 -6.93889e-18 -8.67362e-19" rpy="0 -0 0" />
            <geometry>
                <mesh filename="package://arm/src/meshes/wall_front.stl"/>
            </geometry>
            <material name="plywood"/>
        </collision>
        <visual>
            <origin xyz="0 0 0" rpy="0 -0 0" />
            <geometry>
                <mesh filename="package://arm/src/meshes/top.stl"/>
            </geometry>
            <material name="plywood"/>
        </visual>
        <collision>
            <origin xyz="0 0 0" rpy="0 -0 0" />
            <geometry>
                <mesh filename="package://arm/src/meshes/top.stl"/>
            </geometry>
            <material name="plywood"/>
        </collision>
        <inertial>
            <origin xyz="-0.04596 -3.09902e-06 0.0414358" rpy="0 0 0"/>
            <mass value="1.26177" />
            <inertia ixx="0.001588" ixy="1.973e-07"  ixz="8.28818e-07" iyy="0.00336754" iyz="1.17545e-07" izz="0.00393728" />
        </inertial>
    </link>

    <link name="hip">
        <visual>
            <origin xyz="-6.93889e-18 0 0.062" rpy="-3.14159 -0 4.01069e-70" />
            <geometry>
                <mesh filename="package://arm/src/meshes/side_2.stl"/>
            </geometry>
            <material name="pvc"/>
        </visual>
        <collision>
            <origin xyz="-6.93889e-18 0 0.062" rpy="-3.14159 -0 4.01069e-70" />
            <geometry>
                <mesh filename="package://arm/src/meshes/side_2.stl"/>
            </geometry>
            <material name="pvc"/>
        </collision>
        <visual>
            <origin xyz="-0.0235 2.08167e-17 -0.116" rpy="-3.14159 -0 4.01069e-70" />
            <geometry>
                <mesh filename="package://arm/src/meshes/skf_7202.stl"/>
            </geometry>
            <material name="bearing_material"/>
        </visual>
        <collision>
            <origin xyz="-0.0235 2.08167e-17 -0.116" rpy="-3.14159 -0 4.01069e-70" />
            <geometry>
                <mesh filename="package://arm/src/meshes/skf_7202.stl"/>
            </geometry>
            <material name="bearing_material"/>
        </collision>
        <visual>
            <origin xyz="0 0 0.062" rpy="-3.14159 -0 4.01069e-70" />
            <geometry>
                <mesh filename="package://arm/src/meshes/tree_base.stl"/>
            </geometry>
            <material name="pla"/>
        </visual>
        <collision>
            <origin xyz="0 0 0.062" rpy="-3.14159 -0 4.01069e-70" />
            <geometry>
                <mesh filename="package://arm/src/meshes/tree_base.stl"/>
            </geometry>
            <material name="pla"/>
        </collision>
        <visual>
            <origin xyz="-0.109 -1.38778e-17 -0.013" rpy="-3.14159 -0 4.01069e-70" />
            <geometry>
                <mesh filename="package://arm/src/meshes/big_gear_pelvis.stl"/>
            </geometry>
            <material name="pvc"/>
        </visual>
        <collision>
            <origin xyz="-0.109 -1.38778e-17 -0.013" rpy="-3.14159 -0 4.01069e-70" />
            <geometry>
                <mesh filename="package://arm/src/meshes/big_gear_pelvis.stl"/>
            </geometry>
            <material name="pvc"/>
        </collision>
        <visual>
            <origin xyz="0.0235 2.08167e-17 -0.116" rpy="-3.14159 -0 4.01069e-70" />
            <geometry>
                <mesh filename="package://arm/src/meshes/skf_7202.stl"/>
            </geometry>
            <material name="bearing_material"/>
        </visual>
        <collision>
            <origin xyz="0.0235 2.08167e-17 -0.116" rpy="-3.14159 -0 4.01069e-70" />
            <geometry>
                <mesh filename="package://arm/src/meshes/skf_7202.stl"/>
            </geometry>
            <material name="bearing_material"/>
        </collision>
        <visual>
            <origin xyz="0.009 -0.06775 -0.12275" rpy="1.5708 1.5708 0" />
            <geometry>
                <mesh filename="package://arm/src/meshes/xl430.stl"/>
            </geometry>
            <material name="xl430_material"/>
        </visual>
        <collision>
            <origin xyz="0.009 -0.06775 -0.12275" rpy="1.5708 1.5708 0" />
            <geometry>
                <mesh filename="package://arm/src/meshes/xl430.stl"/>
            </geometry>
            <material name="xl430_material"/>
        </collision>
        <visual>
            <origin xyz="0 0 0.062" rpy="-3.14159 -0 4.01069e-70" />
            <geometry>
                <mesh filename="package://arm/src/meshes/side.stl"/>
            </geometry>
            <material name="pvc"/>
        </visual>
        <collision>
            <origin xyz="0 0 0.062" rpy="-3.14159 -0 4.01069e-70" />
            <geometry>
                <mesh filename="package://arm/src/meshes/side.stl"/>
            </geometry>
            <material name="pvc"/>
        </collision>
        <visual>
            <origin xyz="-0.016 -0.13525 -0.12275" rpy="1.5708 -6.37237e-58 1.5708" />
            <geometry>
                <mesh filename="package://arm/src/meshes/small_gear_shoulder.stl"/>
            </geometry>
            <material name="pvc"/>
        </visual>
        <collision>
            <origin xyz="-0.016 -0.13525 -0.12275" rpy="1.5708 -6.37237e-58 1.5708" />
            <geometry>
                <mesh filename="package://arm/src/meshes/small_gear_shoulder.stl"/>
            </geometry>
            <material name="pvc"/>
        </collision>
        <visual>
            <origin xyz="0 0 0.062" rpy="-3.14159 -0 4.01069e-70" />
            <geometry>
                <mesh filename="package://arm/src/meshes/fixing_base_tree.stl"/>
            </geometry>
            <material name="pla"/>
        </visual>
        <collision>
            <origin xyz="0 0 0.062" rpy="-3.14159 -0 4.01069e-70" />
            <geometry>
                <mesh filename="package://arm/src/meshes/fixing_base_tree.stl"/>
            </geometry>
            <material name="pla"/>
        </collision>
        <inertial>
            <origin xyz="0.000589843 -0.0157104 -0.0737648" rpy="0 0 0"/>
            <mass value="0.468773" />
            <inertia ixx="0.00169453" ixy="1.54024e-05"  ixz="1.84051e-05" iyy="0.00152219" iyz="-0.000280798" izz="0.000693306" />
        </inertial>
    </link>

    <link name="humerus">
        <visual>
            <origin xyz="6.93889e-18 0 0.02" rpy="-1.5708 -9.99986e-31 0" />
            <geometry>
                <mesh filename="package://arm/src/meshes/humerus.stl"/>
            </geometry>
            <material name="pvc"/>
        </visual>
        <collision>
            <origin xyz="6.93889e-18 0 0.02" rpy="-1.5708 -9.99986e-31 0" />
            <geometry>
                <mesh filename="package://arm/src/meshes/humerus.stl"/>
            </geometry>
            <material name="pvc"/>
        </collision>
        <visual>
            <origin xyz="6.93889e-18 0 0.02" rpy="-1.5708 -9.99986e-31 0" />
            <geometry>
                <mesh filename="package://arm/src/meshes/tree_shoulder.stl"/>
            </geometry>
            <material name="pla"/>
        </visual>
        <collision>
            <origin xyz="6.93889e-18 0 0.02" rpy="-1.5708 -9.99986e-31 0" />
            <geometry>
                <mesh filename="package://arm/src/meshes/tree_shoulder.stl"/>
            </geometry>
            <material name="pla"/>
        </collision>
        <visual>
            <origin xyz="0 4.58366e-07 -0.008" rpy="0 -9.99986e-31 0" />
            <geometry>
                <mesh filename="package://arm/src/meshes/big_gear_shoulder.stl"/>
            </geometry>
            <material name="pvc"/>
        </visual>
        <collision>
            <origin xyz="0 4.58366e-07 -0.008" rpy="0 -9.99986e-31 0" />
            <geometry>
                <mesh filename="package://arm/src/meshes/big_gear_shoulder.stl"/>
            </geometry>
            <material name="pvc"/>
        </collision>
        <visual>
            <origin xyz="0 0.16 0.0115" rpy="-0 -1.5708 0" />
            <geometry>
                <mesh filename="package://arm/src/meshes/skf_7202.stl"/>
            </geometry>
            <material name="bearing_material"/>
        </visual>
        <collision>
            <origin xyz="0 0.16 0.0115" rpy="-0 -1.5708 0" />
            <geometry>
                <mesh filename="package://arm/src/meshes/skf_7202.stl"/>
            </geometry>
            <material name="bearing_material"/>
        </collision>
        <visual>
            <origin xyz="6.93889e-18 0 0.02" rpy="-1.5708 -9.99986e-31 0" />
            <geometry>
                <mesh filename="package://arm/src/meshes/fixing_shoulder_tree.stl"/>
            </geometry>
            <material name="pla"/>
        </visual>
        <collision>
            <origin xyz="6.93889e-18 0 0.02" rpy="-1.5708 -9.99986e-31 0" />
            <geometry>
                <mesh filename="package://arm/src/meshes/fixing_shoulder_tree.stl"/>
            </geometry>
            <material name="pla"/>
        </collision>
        <visual>
            <origin xyz="6.47399e-15 0.0969992 -0.033" rpy="1.5708 1.1896e-13 3.14159" />
            <geometry>
                <mesh filename="package://arm/src/meshes/xl430.stl"/>
            </geometry>
            <material name="xl430_material"/>
        </visual>
        <collision>
            <origin xyz="6.47399e-15 0.0969992 -0.033" rpy="1.5708 1.1896e-13 3.14159" />
            <geometry>
                <mesh filename="package://arm/src/meshes/xl430.stl"/>
            </geometry>
            <material name="xl430_material"/>
        </collision>
        <visual>
            <origin xyz="-4.11476e-15 -4.72677e-14 -0.056" rpy="1.5708 1.1896e-13 3.14159" />
            <geometry>
                <mesh filename="package://arm/src/meshes/humerus.stl"/>
            </geometry>
            <material name="pvc"/>
        </visual>
        <collision>
            <origin xyz="-4.11476e-15 -4.72677e-14 -0.056" rpy="1.5708 1.1896e-13 3.14159" />
            <geometry>
                <mesh filename="package://arm/src/meshes/humerus.stl"/>
            </geometry>
            <material name="pvc"/>
        </collision>
        <visual>
            <origin xyz="-1.4575e-07 0.156999 -0.063" rpy="3.14159 1.2326e-32 1.5708" />
            <geometry>
                <mesh filename="package://arm/src/meshes/small_gear_elbow.stl"/>
            </geometry>
            <material name="pvc"/>
        </visual>
        <collision>
            <origin xyz="-1.4575e-07 0.156999 -0.063" rpy="3.14159 1.2326e-32 1.5708" />
            <geometry>
                <mesh filename="package://arm/src/meshes/small_gear_elbow.stl"/>
            </geometry>
            <material name="pvc"/>
        </collision>
        <visual>
            <origin xyz="-1.4575e-07 0.0969993 -0.063" rpy="-3.14159 6.50591e-14 3.14159" />
            <geometry>
                <mesh filename="package://arm/src/meshes/motor_link_xl.stl"/>
            </geometry>
            <material name="pla"/>
        </visual>
        <collision>
            <origin xyz="-1.4575e-07 0.0969993 -0.063" rpy="-3.14159 6.50591e-14 3.14159" />
            <geometry>
                <mesh filename="package://arm/src/meshes/motor_link_xl.stl"/>
            </geometry>
            <material name="pla"/>
        </collision>
        <visual>
            <origin xyz="1.38778e-17 0.16 -0.0475" rpy="-0 1.5708 0" />
            <geometry>
                <mesh filename="package://arm/src/meshes/skf_7202.stl"/>
            </geometry>
            <material name="bearing_material"/>
        </visual>
        <collision>
            <origin xyz="1.38778e-17 0.16 -0.0475" rpy="-0 1.5708 0" />
            <geometry>
                <mesh filename="package://arm/src/meshes/skf_7202.stl"/>
            </geometry>
            <material name="bearing_material"/>
        </collision>
        <inertial>
            <origin xyz="-1.20261e-09 0.079896 -0.0180401" rpy="0 0 0"/>
            <mass value="0.390303" />
            <inertia ixx="0.00200387" ixy="8.02768e-12"  ixz="-2.14146e-11" iyy="0.00041595" iyz="9.04428e-05" izz="0.00180475" />
        </inertial>
    </link>

    <link name="radius">
        <visual>
            <origin xyz="-1.4575e-07 0.120047 -0.058875" rpy="3.14159 1.36944e-13 -1.40694e-13" />
            <geometry>
                <mesh filename="package://arm/src/meshes/motor_link_xl.stl"/>
            </geometry>
            <material name="pla"/>
        </visual>
        <collision>
            <origin xyz="-1.4575e-07 0.120047 -0.058875" rpy="3.14159 1.36944e-13 -1.40694e-13" />
            <geometry>
                <mesh filename="package://arm/src/meshes/motor_link_xl.stl"/>
            </geometry>
            <material name="pla"/>
        </collision>
        <visual>
            <origin xyz="-1.60982e-14 5.07858e-14 -0.026125" rpy="1.5708 6.45103e-17 3.14159" />
            <geometry>
                <mesh filename="package://arm/src/meshes/radius.stl"/>
            </geometry>
            <material name="pvc"/>
        </visual>
        <collision>
            <origin xyz="-1.60982e-14 5.07858e-14 -0.026125" rpy="1.5708 6.45103e-17 3.14159" />
            <geometry>
                <mesh filename="package://arm/src/meshes/radius.stl"/>
            </geometry>
            <material name="pvc"/>
        </collision>
        <visual>
            <origin xyz="6.16174e-15 0.120047 -0.028875" rpy="1.5708 6.45103e-17 3.14159" />
            <geometry>
                <mesh filename="package://arm/src/meshes/xl430.stl"/>
            </geometry>
            <material name="xl430_material"/>
        </visual>
        <collision>
            <origin xyz="6.16174e-15 0.120047 -0.028875" rpy="1.5708 6.45103e-17 3.14159" />
            <geometry>
                <mesh filename="package://arm/src/meshes/xl430.stl"/>
            </geometry>
            <material name="xl430_material"/>
        </collision>
        <visual>
            <origin xyz="-1.4575e-07 0.120047 -0.064875" rpy="3.65598e-13 8.84293e-14 -1.5708" />
            <geometry>
                <mesh filename="package://arm/src/meshes/small_gear_wrist.stl"/>
            </geometry>
            <material name="pvc"/>
        </visual>
        <collision>
            <origin xyz="-1.4575e-07 0.120047 -0.064875" rpy="3.65598e-13 8.84293e-14 -1.5708" />
            <geometry>
                <mesh filename="package://arm/src/meshes/small_gear_wrist.stl"/>
            </geometry>
            <material name="pvc"/>
        </collision>
        <visual>
            <origin xyz="-5.66214e-15 0.155 -0.008625" rpy="-1.75409e-14 -1.5708 0" />
            <geometry>
                <mesh filename="package://arm/src/meshes/skf_7202.stl"/>
            </geometry>
            <material name="bearing_material"/>
        </visual>
        <collision>
            <origin xyz="-5.66214e-15 0.155 -0.008625" rpy="-1.75409e-14 -1.5708 0" />
            <geometry>
                <mesh filename="package://arm/src/meshes/skf_7202.stl"/>
            </geometry>
            <material name="bearing_material"/>
        </collision>
        <visual>
            <origin xyz="-2.77556e-16 5.89806e-16 -0.025875" rpy="-1.5708 4.23081e-33 -2.31597e-30" />
            <geometry>
                <mesh filename="package://arm/src/meshes/radius.stl"/>
            </geometry>
            <material name="pvc"/>
        </visual>
        <collision>
            <origin xyz="-2.77556e-16 5.89806e-16 -0.025875" rpy="-1.5708 4.23081e-33 -2.31597e-30" />
            <geometry>
                <mesh filename="package://arm/src/meshes/radius.stl"/>
            </geometry>
            <material name="pvc"/>
        </collision>
            <visual>
            <origin xyz="-4.996e-15 0.155 -0.043375" rpy="-3.14159 1.5708 0" />
            <geometry>
                <mesh filename="package://arm/src/meshes/skf_7202.stl"/>
            </geometry>
            <material name="bearing_material"/>
        </visual>
        <collision>
            <origin xyz="-4.996e-15 0.155 -0.043375" rpy="-3.14159 1.5708 0" />
            <geometry>
                <mesh filename="package://arm/src/meshes/skf_7202.stl"/>
            </geometry>
            <material name="bearing_material"/>
        </collision>
        <visual>
            <origin xyz="0 0 -0.026" rpy="-1.5708 4.23081e-33 -2.31597e-30" />
            <geometry>
                <mesh filename="package://arm/src/meshes/tree_elbow.stl"/>
            </geometry>
            <material name="pla"/>
        </visual>
        <collision>
            <origin xyz="0 0 -0.026" rpy="-1.5708 4.23081e-33 -2.31597e-30" />
            <geometry>
                <mesh filename="package://arm/src/meshes/tree_elbow.stl"/>
            </geometry>
            <material name="pla"/>
        </collision>
        <visual>
            <origin xyz="-0.003 2.23432e-15 0.018" rpy="2.50022e-13 -8.51559e-14 1.05124e-14" />
            <geometry>
                <mesh filename="package://arm/src/meshes/big_gear_elbow.stl"/>
            </geometry>
            <material name="pvc"/>
        </visual>
        <collision>
            <origin xyz="-0.003 2.23432e-15 0.018" rpy="2.50022e-13 -8.51559e-14 1.05124e-14" />
            <geometry>
                <mesh filename="package://arm/src/meshes/big_gear_elbow.stl"/>
            </geometry>
            <material name="pvc"/>
        </collision>
        <inertial>
            <origin xyz="-1.50407e-09 0.0815245 -0.0176273" rpy="0 0 0"/>
            <mass value="0.380955" />
            <inertia ixx="0.00183593" ixy="2.20361e-11"  ixz="-2.38889e-11" iyy="0.000351507" iyz="0.000297264" izz="0.00167685" />
        </inertial>
    </link>

    <link name="hand">
        <visual>
            <origin xyz="0.00642248 0.228 -0.0206241" rpy="1.5708 -1.0472 -3.14159" />
            <geometry>
                <mesh filename="package://arm/src/meshes/finger.stl"/>
            </geometry>
            <material name="pla"/>
        </visual>
        <collision>
            <origin xyz="0.00642248 0.228 -0.0206241" rpy="1.5708 -1.0472 -3.14159" />
            <geometry>
                <mesh filename="package://arm/src/meshes/finger.stl"/>
            </geometry>
            <material name="pla"/>
        </collision>
        <visual>
            <origin xyz="0 0.1165 -0.0105" rpy="-1.66533e-16 1.5708 0" />
            <geometry>
                <mesh filename="package://arm/src/meshes/cover_rod.stl"/>
            </geometry>
            <material name="pla"/>
        </visual>
        <collision>
            <origin xyz="0 0.1165 -0.0105" rpy="-1.66533e-16 1.5708 0" />
            <geometry>
                <mesh filename="package://arm/src/meshes/cover_rod.stl"/>
            </geometry>
            <material name="pla"/>
        </collision>
        <visual>
            <origin xyz="4.1576e-07 0.061 -0.0105" rpy="-1.5708 1.5708 0" />
            <geometry>
                <mesh filename="package://arm/src/meshes/ax_12w.stl"/>
            </geometry>
            <material name="ax_12w_material">
                <color rgba="0.101961 0.101961 0.101961 1.0"/>
            </material>
        </visual>
        <collision>
            <origin xyz="4.1576e-07 0.061 -0.0105" rpy="-1.5708 1.5708 0" />
            <geometry>
                <mesh filename="package://arm/src/meshes/ax_12w.stl"/>
            </geometry>
            <material name="ax_12w_material">
                <color rgba="0.101961 0.101961 0.101961 1.0"/>
            </material>
        </collision>
        <visual>
            <origin xyz="4.55455e-05 0.066 -0.010477" rpy="1.0472 -2.73837e-16 1.5708" />
            <geometry>
                <mesh filename="package://arm/src/meshes/nut.stl"/>
            </geometry>
            <material name="steel"/>
        </visual>
        <collision>
            <origin xyz="4.55455e-05 0.066 -0.010477" rpy="1.0472 -2.73837e-16 1.5708" />
            <geometry>
                <mesh filename="package://arm/src/meshes/nut.stl"/>
            </geometry>
            <material name="steel"/>
        </collision>
        <visual>
            <origin xyz="0 0 -0.0105" rpy="1.5708 8.46163e-33 -1.43384e-30" />
            <geometry>
                <mesh filename="package://arm/src/meshes/fixing_camera.stl"/>
            </geometry>
            <material name="pla"/>
        </visual>
        <collision>
            <origin xyz="0 0 -0.0105" rpy="1.5708 8.46163e-33 -1.43384e-30" />
            <geometry>
                <mesh filename="package://arm/src/meshes/fixing_camera.stl"/>
            </geometry>
            <material name="pla"/>
        </collision>
        <visual>
            <origin xyz="0.00555645 0.228 0.00012406" rpy="1.5708 1.0472 3.14159" />
            <geometry>
                <mesh filename="package://arm/src/meshes/finger.stl"/>
            </geometry>
            <material name="pla"/>
        </visual>
        <collision>
            <origin xyz="0.00555645 0.228 0.00012406" rpy="1.5708 1.0472 3.14159" />
            <geometry>
                <mesh filename="package://arm/src/meshes/finger.stl"/>
            </geometry>
            <material name="pla"/>
        </collision>
        <visual>
            <origin xyz="0 0 -0.0105" rpy="1.5708 8.46163e-33 -1.43384e-30" />
            <geometry>
                <mesh filename="package://arm/src/meshes/tree_wrist.stl"/>
            </geometry>
            <material name="pla"/>
        </visual>
        <collision>
            <origin xyz="0 0 -0.0105" rpy="1.5708 8.46163e-33 -1.43384e-30" />
            <geometry>
                <mesh filename="package://arm/src/meshes/tree_wrist.stl"/>
            </geometry>
            <material name="pla"/>
        </collision>
        <visual>
            <origin xyz="4.1576e-07 0.10762 -0.0105" rpy="-1.5708 -1.73885e-16 -3.14159" />
            <geometry>
                <mesh filename="package://arm/src/meshes/fixing_ax.stl"/>
            </geometry>
            <material name="pla"/>
        </visual>
        <collision>
            <origin xyz="4.1576e-07 0.10762 -0.0105" rpy="-1.5708 -1.73885e-16 -3.14159" />
            <geometry>
                <mesh filename="package://arm/src/meshes/fixing_ax.stl"/>
            </geometry>
            <material name="pla"/>
        </collision>
        <visual>
            <origin xyz="-0.0119789 0.228 -0.011" rpy="-1.5708 -3.55981e-26 5.55112e-17" />
            <geometry>
                <mesh filename="package://arm/src/meshes/finger.stl"/>
            </geometry>
            <material name="pla"/>
        </visual>
        <collision>
            <origin xyz="-0.0119789 0.228 -0.011" rpy="-1.5708 -3.55981e-26 5.55112e-17" />
            <geometry>
                <mesh filename="package://arm/src/meshes/finger.stl"/>
            </geometry>
            <material name="pla"/>
        </collision>
        <visual>
            <origin xyz="0.000298804 0.1165 -0.0105158" rpy="-1.38778e-16 1.5708 0" />
            <geometry>
                <mesh filename="package://arm/src/meshes/fixing_rod.stl"/>
            </geometry>
            <material name="pla"/>
        </visual>
        <collision>
            <origin xyz="0.000298804 0.1165 -0.0105158" rpy="-1.38778e-16 1.5708 0" />
            <geometry>
                <mesh filename="package://arm/src/meshes/fixing_rod.stl"/>
            </geometry>
            <material name="pla"/>
        </collision>
        <visual>
            <origin xyz="-0.0352 0 -0.0485" rpy="-1.7373e-27 -2.92088e-30 1.83596e-29" />
            <geometry>
                <mesh filename="package://arm/src/meshes/big_gear_wrist.stl"/>
            </geometry>
            <material name="pvc"/>
        </visual>
        <collision>
            <origin xyz="-0.0352 0 -0.0485" rpy="-1.7373e-27 -2.92088e-30 1.83596e-29" />
            <geometry>
                <mesh filename="package://arm/src/meshes/big_gear_wrist.stl"/>
            </geometry>
            <material name="pvc"/>
        </collision>
        <visual>
            <origin xyz="0.000500416 0.10624 -0.0105" rpy="5.79785e-17 1.66533e-16 1.5708" />
            <geometry>
                <mesh filename="package://arm/src/meshes/threaded_rod.stl"/>
            </geometry>
            <material name="steel"/>
        </visual>
        <collision>
            <origin xyz="0.000500416 0.10624 -0.0105" rpy="5.79785e-17 1.66533e-16 1.5708" />
            <geometry>
                <mesh filename="package://arm/src/meshes/threaded_rod.stl"/>
            </geometry>
            <material name="steel"/>
        </collision>
        <visual>
            <origin xyz="0 0 -0.0105" rpy="1.5708 8.46163e-33 -1.43384e-30" />
            <geometry>
                <mesh filename="package://arm/src/meshes/fixing_hand.stl"/>
            </geometry>
            <material name="pla"/>
        </visual>
        <collision>
            <origin xyz="0 0 -0.0105" rpy="1.5708 8.46163e-33 -1.43384e-30" />
            <geometry>
                <mesh filename="package://arm/src/meshes/fixing_hand.stl"/>
            </geometry>
            <material name="pla"/>
        </collision>
        <visual>
            <origin xyz="5.55112e-17 0.14 -0.0105" rpy="-5.55112e-17 1.5708 0" />
            <geometry>
                <mesh filename="package://arm/src/meshes/fixing_finger.stl"/>
            </geometry>
            <material name="pla"/>
        </visual>
        <collision>
            <origin xyz="5.55112e-17 0.14 -0.0105" rpy="-5.55112e-17 1.5708 0" />
            <geometry>
                <mesh filename="package://arm/src/meshes/fixing_finger.stl"/>
            </geometry>
            <material name="pla"/>
        </collision>
        <visual>
            <origin xyz="4.1576e-07 0.06036 -0.0105" rpy="-1.5708 1.5708 0" />
            <geometry>
                <mesh filename="package://arm/src/meshes/horn^horn_assembly_ax-18a.stl"/>
            </geometry>
            <material name="horn^horn_assembly_ax-18a_material">
                <color rgba="0.101961 0.101961 0.101961 1.0"/>
            </material>
        </visual>
        <collision>
            <origin xyz="4.1576e-07 0.06036 -0.0105" rpy="-1.5708 1.5708 0" />
            <geometry>
                <mesh filename="package://arm/src/meshes/horn^horn_assembly_ax-18a.stl"/>
            </geometry>
            <material name="horn^horn_assembly_ax-18a_material">
                <color rgba="0.101961 0.101961 0.101961 1.0"/>
            </material>
        </collision>
        <inertial>
            <origin xyz="0.00378438 0.0815063 -0.01325" rpy="0 0 0"/>
            <mass value="0.191614" />
            <inertia ixx="0.000505108" ixy="7.20463e-06"  ixz="-2.00489e-06" iyy="7.70856e-05" iyz="-4.29693e-05" izz="0.000508508" />
        </inertial>
    </link>

    <link name="camera">
        <visual>
            <origin xyz="-0.0505004 -3.46945e-18 -0.083" rpy="3.14159 2.46329e-30 -1.58188e-33" />
            <geometry>
                <mesh filename="package://arm/src/meshes/camera.stl"/>
            </geometry>
            <material name="camera_material">
                <color rgba="0.282353 0.54902 0.160784 1.0"/>
            </material>
        </visual>
        <collision>
            <origin xyz="-0.0505004 -3.46945e-18 -0.083" rpy="3.14159 2.46329e-30 -1.58188e-33" />
            <geometry>
                <mesh filename="package://arm/src/meshes/camera.stl"/>
            </geometry>
            <material name="camera_material">
                <color rgba="0.282353 0.54902 0.160784 1.0"/>
            </material>
        </collision>
        <inertial>
            <origin xyz="-0.003 -1.23123e-19 -0.0015" rpy="0 0 0"/>
            <mass value="0.000135" />
            <inertia ixx="5.0625e-10" ixy="-1.43042e-42"  ixz="-4.72086e-41" iyy="5.0625e-10" iyz="-2.1031e-39" izz="8.1e-10" />
        </inertial>
    </link>

    <joint name="camera" type="fixed">
        <origin xyz="0.0560004 0.08 -0.0105" rpy="1.5708 -1.70787e-28 1.9082e-16" />
        <parent link="hand" />
        <child link="camera" />
        <axis xyz="0 0 1"/>
        <limit effort="1" velocity="20" />
        <joint_properties friction="0.0"/>
    </joint>

    <link name="target">
        <visual>
            <origin xyz="6.66272e-05 -0.01 -0.0132287" rpy="-1.5708 -1.5708 0" />
            <geometry>
                <mesh filename="package://arm/src/meshes/target.stl"/>
            </geometry>
            <material name="target_material">
                <color rgba="0.823529 0.623529 0.0352941 1.0"/>
            </material>
        </visual>
        <collision>
            <origin xyz="6.66272e-05 -0.01 -0.0132287" rpy="-1.5708 -1.5708 0" />
            <geometry>
                <mesh filename="package://arm/src/meshes/target.stl"/>
            </geometry>
            <material name="target_material">
                <color rgba="0.823529 0.623529 0.0352941 1.0"/>
            </material>
        </collision>
        <inertial>
            <origin xyz="1.35525e-20 -6.41848e-17 -0.0015" rpy="0 0 0"/>
            <mass value="3.375e-05" />
            <inertia ixx="5.0625e-11" ixy="-1.00157e-41"  ixz="3.08861e-40" iyy="5.0625e-11" iyz="-3.25261e-41" izz="5.0625e-11" />
        </inertial>
    </link>

    <joint name="fixed" type="fixed">
        <parent link="origin"/>
        <child link="base"/>
    </joint>

    <joint name="target" type="fixed">
        <origin xyz="0.000500416 0.23624 -0.0105" rpy="1.5708 1.5708 0" />
        <parent link="hand" />
        <child link="target" />
        <axis xyz="0 0 1"/>
        <limit effort="1" velocity="20" />
        <joint_properties friction="0.0"/>
    </joint>

    <joint name="wrist" type="revolute">
        <origin xyz="-4.77396e-15 0.155 -0.014125" rpy="2.22045e-16 -2.15076e-25 -4.74015e-14" />
        <parent link="radius" />
        <child link="hand" />
        <axis xyz="0 0 1"/>
        <limit effort="1" velocity="20" lower="0" upper="1.5708"/>
        <joint_properties friction="0.0"/>
    </joint>

    <joint name="elbow" type="revolute">
        <origin xyz="1.38778e-17 0.16 -0.042" rpy="3.14159 1.78606e-16 1.5708" />
        <parent link="humerus" />
        <child link="radius" />
        <axis xyz="0 0 1"/>
        <limit effort="1" velocity="20" lower="-1.5708" upper="1.0472"/>
        <joint_properties friction="0.0"/>
    </joint>

    <joint name="shoulder" type="revolute">
        <origin xyz="-0.018 2.08167e-17 -0.116" rpy="-1.5708 7.82376e-14 1.5708" />
        <parent link="hip" />
        <child link="humerus" />
        <axis xyz="0 0 1"/>
        <limit effort="1" velocity="20" lower="-1.5708" upper="0.698132"/>
        <joint_properties friction="0.0"/>
    </joint>

    <joint name="pelvis" type="revolute">
        <origin xyz="-0.06 6.93889e-18 0.069" rpy="3.14159 -1.19271e-28 -1.5708" />
        <parent link="base" />
        <child link="hip" />
        <axis xyz="0 0 1"/>
        <limit effort="1" velocity="20" lower="-1.5708" upper="1.5708"/>
        <joint_properties friction="0.0"/>
    </joint>

</robot>
